Workbook

Sheet README
A1: Ingredient database: nutrition + Provigo prices
A2: Used by the Streamlit app / recipe_aggregator.py. Prices are in Canadian dollars (CAD). Built 4 Oct 2026.
A4: WHAT TO EDIT
A5: Blue cells on the 'Ingredients' sheet are inputs: calories, protein, pack size, pack unit, pack price, status, source. Black cells are formulas - do not type over them.
A6: To change a price: edit 'Pack price (CAD)' (and 'Pack size' if the pack changed). Cost per 100 g and unit price update by themselves.
A7: To add an ingredient: add a row at the bottom of 'Ingredients' and copy the formulas in columns J-M from the row above. Put every spelling used in your recipes in 'Names used in recipes' (comma-separated).
A8: If a recipe uses a unit other than g / ml / kg / l for an ingredient (tablespoons, pieces, strips...), add a row to 'Unit conversions' with the grams per unit.
A10: HOW 'PACK' WORKS
A11: The pack is what you can typically buy in store (e.g. 1 kg of rice, 12 eggs). 'Cost per 100 g' = pack price / pack weight x 100. For items sold by count (eggs, bacon strips, avocados) the 'Unit price' column shows the price per unit instead.
A12: Items sold by weight (loose tomatoes, green beans) are priced in 100 g steps so the 'cost to buy' is not rounded up to a whole kilogram.
A14: PRICE STATUS
A15: Provigo listing: the price was shown on a provigo.ca page when I looked it up (regular price, not the sale price).
... A23: Calories and protein for ingredients that were already in your nutrition_db.xlsx are your original values (unchanged). New ingredients use typical USDA FoodData Central values per 100 g, or approximate label values where marked.

Sheet Ingredients
A1: Ingredient database: nutrition (per 100 g) and Provigo prices (CAD)
A2: Blue = inputs you can edit; black = formulas. Yellow price = estimate, replace it. See the README sheet for details.
A3: Ingredient | B3: Names used in recipes | C3: Kcal per 100 g | D3: Protein per 100 g (g) | E3: Nutrition source | F3: Product priced | G3: Pack size | H3: Pack unit | I3: Pack price (CAD) | J3: Pack weight (g) | K3: Cost per 100 g (CAD) | L3: Unit price (CAD) | M3: Unit price per | N3: Price status | O3: Price source | P3: Notes
A4: All-purpose flour | B4: all purpose flour, flour | C4: 364 | D4: 10.3 | E4: USDA FoodData Central (typical value) | F4: No Name All-Purpose Flour 2.5 kg | G4: 2500 | H4: g | I4: 4.5 | J4: =IF(OR(G4="",I4=""),"",G4*IF(H4="g",1,IF(H4="kg",1000,SUMIFS('Unit conversions'!$C:$C,'Unit conversions'!$A:$A,$A4,'Unit conversions'!$B:$B,H4)))) -> 2500 | K4: =IF(OR(J4="",J4=0),"",I4/J4*100) -> 0.18 | L4: =IF(OR(G4="",I4=""),"",IF(OR(H4="g",H4="ml"),I4/G4*100,I4/G4)) -> 0.18 | M4: =IF(H4="","",IF(OR(H4="g",H4="ml"),"100 "&H4,H4)) -> 100 g | N4: Provigo unit price (derived) | O4: https://www.provigo.ca/en/food/pantry/baking-essentials/flours/c/29695 | P4: Provigo shows $0.18/100 g (= $4.50 for 2.5 kg). Robin Hood 2.5 kg is about $0.20-0.30/100 g.
A5: Avocado | C5: 200 | D5: 2 | E5: Your nutrition_db.xlsx | F5: Avocado, single | G5: 1 | H5: piece | I5: 2 | J5: =IF(OR(G5="",I5=""),"",G5*IF(H5="g",1,IF(H5="kg",1000,SUMIFS('Unit conversions'!$C:$C,'Unit conversions'!$A:$A,$A5,'Unit conversions'!$B:$B,H5)))) -> 100 | K5: =IF(OR(J5="",J5=0),"",I5/J5*100) -> 2 | L5: =IF(OR(G5="",I5=""),"",IF(OR(H5="g",H5="ml"),I5/G5*100,I5/G5)) -> 2 | M5: =IF(H5="","",IF(OR(H5="g",H5="ml"),"100 "&H5,H5)) -> piece | N5: Provigo listing | O5: https://www.provigo.ca/en/food/fruits-vegetables/fresh-fruits/avocado-tropical-fruits/c/29723 | P5: 1 piece = 100 g (your note). A bag of 3-4 is cheaper per avocado.
A6: Bacon | C6: 541 | D6: 37 | E6: USDA FoodData Central (typical value) - cooked | F6: No Name Mild Sugar Cured Bacon 375 g | G6: 31 | H6: strip | I6: 6.5 | J6: =IF(OR(G6="",I6=""),"",G6*IF(H6="g",1,IF(H6="kg",1000,SUMIFS('Unit conversions'!$C:$C,'Unit conversions'!$A:$A,$A6,'Unit conversions'!$B:$B,H6)))) -> 248 | K6: =IF(OR(J6="",J6=0),"",I6/J6*100) -> 2.6209677 | L6: =IF(OR(G6="",I6=""),"",IF(OR(H6="g",H6="ml"),I6/G6*100,I6/G6)) -> 0.20967742 | M6: =IF(H6="","",IF(OR(H6="g",H6="ml"),"100 "&H6,H6)) -> strip | N6: Provigo listing | O6: https://www.provigo.ca/en/food/meat/bacon/c/59252 | P6: Regular price $6.50 ($6.00 on sale when buying 2). ~31 slices per 375 g pack is an assumption. Nutrition is per 100 g COOKED; 1 strip = 8 g cooked.
A7: Baking powder | C7: 53 | D7: 0 | E7: USDA FoodData Central (typical value) | F7: No Name Baking Powder 450 g | G7: 450 | H7: g | I7: 6.48 | J7: =IF(OR(G7="",I7=""),"",G7*IF(H7="g",1,IF(H7="kg",1000,SUMIFS('Unit conversions'!$C:$C,'Unit conversions'!$A:$A,$A7,'Unit conversions'!$B:$B,H7)))) -> 450 | K7: =IF(OR(J7="",J7=0),"",I7/J7*100) -> 1.44 | L7: =IF(OR(G7="",I7=""),"",IF(OR(H7="g",H7="ml"),I7/G7*100,I7/G7)) -> 1.44 | M7: =IF(H7="","",IF(OR(H7="g",H7="ml"),"100 "&H7,H7)) -> 100 g | N7: Provigo unit price (derived) | O7: https://www.provigo.ca/en/food/pantry/baking-essentials/baking-soda-powder-yeast/c/29696 | P7: Provigo shows $1.44/100 g. Magic 225 g is about $2.44/100 g.
A8: Beef | C8: 131 | D8: 21 | E8: Your nutrition_db.xlsx | F8: Lean ground beef, 900 g | G8: 900 | H8: g | I8: 19.5 | J8: =IF(OR(G8="",I8=""),"",G8*IF(H8="g",1,IF(H8="kg",1000,SUMIFS('Unit conversions'!$C:$C,'Unit conversions'!$A:$A,$A8,'Unit conversions'!$B:$B,H8)))) -> 900 | K8: =IF(OR(J8="",J8=0),"",I8/J8*100) -> 2.1666667 | L8: =IF(OR(G8="",I8=""),"",IF(OR(H8="g",H8="ml"),I8/G8*100,I8/G8)) -> 2.1666667 | M8: =IF(H8="","",IF(OR(H8="g",H8="ml"),"100 "&H8,H8)) -> 100 g | N8: Your recipe sheet | O8: Your recipe sheet (beef_taco_potato_bowl.xlsx) | P8: Provigo lean ground beef listings run about $2.00-2.42/100 g, so $2.17/100 g is consistent.
A9: Beef broth | C9: 215 | D9: 10 | E9: Approximate (typical product label) | F9: Beef bouillon cubes, box of 6 | G9: 6 | H9: piece | I9: 6.56 | J9: =IF(OR(G9="",I9=""),"",G9*IF(H9="g",1,IF(H9="kg",1000,SUMIFS('Unit conversions'!$C:$C,'Unit conversions'!$A:$A,$A9,'Unit conversions'!$B:$B,H9)))) -> 60 | K9: =IF(OR(J9="",J9=0),"",I9/J9*100) -> 10.933333 | L9: =IF(OR(G9="",I9=""),"",IF(OR(H9="g",H9="ml"),I9/G9*100,I9/G9)) -> 1.0933333 | M9: =IF(H9="","",IF(OR(H9="g",H9="ml"),"100 "&H9,H9)) -> piece | N9: Your recipe sheet | O9: Your recipe sheet (beef_taco_potato_bowl.xlsx: =6.56/6 per piece) | P9: 1 piece = 1 cube, ~10 g (assumption). Nutrition is a rough value for dry bouillon.
A10: Blueberries | C10: 57 | D10: 0.7 | E10: USDA FoodData Central (typical value) | F10: Blueberries, half pint 170 g | G10: 170 | H10: g | I10: 5.5 | J10: =IF(OR(G10="",I10=""),"",G10*IF(H10="g",1,IF(H10="kg",1000,SUMIFS('Unit conversions'!$C:$C,'Unit conversions'!$A:$A,$A10,'Unit conversions'!$B:$B,H10)))) -> 170 | K10: =IF(OR(J10="",J10=0),"",I10/J10*100) -> 3.2352941 | L10: =IF(OR(G10="",I10=""),"",IF(OR(H10="g",H10="ml"),I10/G10*100,I10/G10)) -> 3.2352941 | M10: =IF(H10="","",IF(OR(H10="g",H10="ml"),"100 "&H10,H10)) -> 100 g | N10: Provigo listing | O10: https://www.provigo.ca/en/food/fruits-vegetables/fresh-fruits/berries-cherries/blueberries/c/34467 | P10: Fresh, out of season. Frozen No Name blueberries (300 g) were listed at $3.00 ($1.00/100 g) if frozen is fine.
A11: Butter | C11: 717 | D11: 0.9 | E11: Your nutrition_db.xlsx | F11: Lactantia Unsalted Butter 454 g | G11: 454 | H11: g | I11: 8.99 | J11: =IF(OR(G11="",I11=""),"",G11*IF(H11="g",1,IF(H11="kg",1000,SUMIFS('Unit conversions'!$C:$C,'Unit conversions'!$A:$A,$A11,'Unit conversions'!$B:$B,H11)))) -> 454 | K11: =IF(OR(J11="",J11=0),"",I11/J11*100) -> 1.9801762 | L11: =IF(OR(G11="",I11=""),"",IF(OR(H11="g",H11="ml"),I11/G11*100,I11/G11)) -> 1.9801762 | M11: =IF(H11="","",IF(OR(H11="g",H11="ml"),"100 "&H11,H11)) -> 100 g | N11: Provigo listing | O11: https://www.provigo.ca/en/food/natural-and-organic/dairy-and-eggs/butter-and-margarine/c/59392 | P11: Not used in your current recipes.
A12: Cheddar | C12: 403 | D12: 24.9 | E12: Your nutrition_db.xlsx | F12: P'tit Quebec Old Cheddar 400 g | G12: 400 | H12: g | I12: 6.5 | J12: =IF(OR(G12="",I12=""),"",G12*IF(H12="g",1,IF(H12="kg",1000,SUMIFS('Unit conversions'!$C:$C,'Unit conversions'!$A:$A,$A12,'Unit conversions'!$B:$B,H12)))) -> 400 | K12: =IF(OR(J12="",J12=0),"",I12/J12*100) -> 1.625 | L12: =IF(OR(G12="",I12=""),"",IF(OR(H12="g",H12="ml"),I12/G12*100,I12/G12)) -> 1.625 | M12: =IF(H12="","",IF(OR(H12="g",H12="ml"),"100 "&H12,H12)) -> 100 g | N12: Provigo listing | O12: https://www.provigo.ca/en/food/deli/deli-cheese/parmesan-hard-cheese/c/29742 | P12: No Name Old Cheddar 400 g is cheaper (~$1.62/100 g).
A13: Cherry tomatoes | B13: grape tomatoes | C13: 18 | D13: 0.9 | E13: USDA FoodData Central (typical value) | F13: Farmer's Market Grape Tomatoes 283 g | G13: 283 | H13: g | I13: 5.5 | J13: =IF(OR(G13="",I13=""),"",G13*IF(H13="g",1,IF(H13="kg",1000,SUMIFS('Unit conversions'!$C:$C,'Unit conversions'!$A:$A,$A13,'Unit conversions'!$B:$B,H13)))) -> 283 | K13: =IF(OR(J13="",J13=0),"",I13/J13*100) -> 1.9434629 | L13: =IF(OR(G13="",I13=""),"",IF(OR(H13="g",H13="ml"),I13/G13*100,I13/G13)) -> 1.9434629 | M13: =IF(H13="","",IF(OR(H13="g",H13="ml"),"100 "&H13,H13)) -> 100 g | N13: Provigo listing | O13: https://www.provigo.ca/en/food/fruits-vegetables/fresh-vegetables/tomatoes-peppers/tomatoes/c/34502 | P13: Another Provigo listing showed $1.77/100 g (about $5.00).
A14: Chicken | C14: 106 | D14: 23 | E14: Your nutrition_db.xlsx | F14: Chicken breast, boneless skinless, club pack (~1.18 kg) | G14: 1180 | H14: g | I14: 23.33 | J14: =IF(OR(G14="",I14=""),"",G14*IF(H14="g",1,IF(H14="kg",1000,SUMIFS('Unit conversions'!$C:$C,'Unit conversions'!$A:$A,$A14,'Unit conversions'!$B:$B,H14)))) -> 1180 | K14: =IF(OR(J14="",J14=0),"",I14/J14*100) -> 1.9771186 | L14: =IF(OR(G14="",I14=""),"",IF(OR(H14="g",H14="ml"),I14/G14*100,I14/G14)) -> 1.9771186 | M14: =IF(H14="","",IF(OR(H14="g",H14="ml"),"100 "&H14,H14)) -> 100 g | N14: Provigo listing | O14: https://www.provigo.ca/en/food/prepared-meals/rotisserie-fried-chicken/rotisserie-chicken/c/29636 | P14: Sold by weight at $19.82/kg ($8.99/lb); $23.33 is Provigo's estimate for a ~1.18 kg tray. Your nutrition values look like RAW breast (cooked is ~165 kcal / 31 g protein per 100 g); check which weight your recipes use.
A15: Chocolate chips | C15: 480 | D15: 4.2 | E15: USDA FoodData Central (typical value) | F15: PC The Decadent Semi-Sweet Chocolate Chips 300 g | G15: 300 | H15: g | I15: 5 | J15: =IF(OR(G15="",I15=""),"",G15*IF(H15="g",1,IF(H15="kg",1000,SUMIFS('Unit conversions'!$C:$C,'Unit conversions'!$A:$A,$A15,'Unit conversions'!$B:$B,H15)))) -> 300 | K15: =IF(OR(J15="",J15=0),"",I15/J15*100) -> 1.6666667 | L15: =IF(OR(G15="",I15=""),"",IF(OR(H15="g",H15="ml"),I15/G15*100,I15/G15)) -> 1.6666667 | M15: =IF(H15="","",IF(OR(H15="g",H15="ml"),"100 "&H15,H15)) -> 100 g | N15: Provigo unit price (derived) | O15: https://www.provigo.ca/en/food/pantry/baking-essentials/chocolate-cocoa/c/29877 | P15: Provigo shows $1.67/100 g.
A16: Cornstarch | B16: corn starch | C16: 381 | D16: 0.3 | E16: USDA FoodData Central (typical value) | F16: No Name 100% Pure Corn Starch 454 g | G16: 454 | H16: g | I16: 4 | J16: =IF(OR(G16="",I16=""),"",G16*IF(H16="g",1,IF(H16="kg",1000,SUMIFS('Unit conversions'!$C:$C,'Unit conversions'!$A:$A,$A16,'Unit conversions'!$B:$B,H16)))) -> 454 | K16: =IF(OR(J16="",J16=0),"",I16/J16*100) -> 0.88105727 | L16: =IF(OR(G16="",I16=""),"",IF(OR(H16="g",H16="ml"),I16/G16*100,I16/G16)) -> 0.88105727 | M16: =IF(H16="","",IF(OR(H16="g",H16="ml"),"100 "&H16,H16)) -> 100 g | N16: Provigo listing | O16: https://www.provigo.ca/en/food/pantry/baking-essentials/baking-soda-powder-yeast/c/29696
A17: Courgette | B17: zucchini | C17: 20 | D17: 1 | E17: Your nutrition_db.xlsx | J17: =IF(OR(G17="",I17=""),"",G17*IF(H17="g",1,IF(H17="kg",1000,SUMIFS('Unit conversions'!$C:$C,'Unit conversions'!$A:$A,$A17,'Unit conversions'!$B:$B,H17)))) | K17: =IF(OR(J17="",J17=0),"",I17/J17*100) | L17: =IF(OR(G17="",I17=""),"",IF(OR(H17="g",H17="ml"),I17/G17*100,I17/G17)) | M17: =IF(H17="","",IF(OR(H17="g",H17="ml"),"100 "&H17,H17)) | N17: Not priced yet | P17: Not used in your current recipes. 1 piece = 400 g (your note).
A18: Creme liquide | B18: creme liquide, crème liquide | C18: 191 | D18: 2.6 | E18: Your nutrition_db.xlsx | J18: =IF(OR(G18="",I18=""),"",G18*IF(H18="g",1,IF(H18="kg",1000,SUMIFS('Unit conversions'!$C:$C,'Unit conversions'!$A:$A,$A18,'Unit conversions'!$B:$B,H18)))) | K18: =IF(OR(J18="",J18=0),"",I18/J18*100) | L18: =IF(OR(G18="",I18=""),"",IF(OR(H18="g",H18="ml"),I18/G18*100,I18/G18)) | M18: =IF(H18="","",IF(OR(H18="g",H18="ml"),"100 "&H18,H18)) | N18: Not priced yet | P18: Not used in your current recipes.
A19: Crepes | C19: 164 | D19: 6 | E19: Your nutrition_db.xlsx | J19: =IF(OR(G19="",I19=""),"",G19*IF(H19="g",1,IF(H19="kg",1000,SUMIFS('Unit conversions'!$C:$C,'Unit conversions'!$A:$A,$A19,'Unit conversions'!$B:$B,H19)))) | K19: =IF(OR(J19="",J19=0),"",I19/J19*100) | L19: =IF(OR(G19="",I19=""),"",IF(OR(H19="g",H19="ml"),I19/G19*100,I19/G19)) | M19: =IF(H19="","",IF(OR(H19="g",H19="ml"),"100 "&H19,H19)) | N19: Not priced yet | P19: Not used in your current recipes. One crepe is 50 g (your note).
A20: Dark chocolate | C20: 522 | D20: 7 | E20: Your nutrition_db.xlsx | F20: No Name Baking Chocolate, Semi-Sweet 200 g | G20: 200 | H20: g | I20: 4 | J20: =IF(OR(G20="",I20=""),"",G20*IF(H20="g",1,IF(H20="kg",1000,SUMIFS('Unit conversions'!$C:$C,'Unit conversions'!$A:$A,$A20,'Unit conversions'!$B:$B,H20)))) -> 200 | K20: =IF(OR(J20="",J20=0),"",I20/J20*100) -> 2 | L20: =IF(OR(G20="",I20=""),"",IF(OR(H20="g",H20="ml"),I20/G20*100,I20/G20)) -> 2 | M20: =IF(H20="","",IF(OR(H20="g",H20="ml"),"100 "&H20,H20)) -> 100 g | N20: Provigo unit price (derived) | O20: https://www.provigo.ca/en/food/pantry/baking-essentials/chocolate-cocoa/c/29877 | P20: Semi-sweet baking chocolate used as a stand-in ($2.00/100 g). Replace with your actual dark chocolate bar's price.
A21: Egg | B21: eggs | C21: 147 | D21: 13 | E21: Your nutrition_db.xlsx | F21: No Name Large Size Eggs, 12 pack | G21: 12 | H21: unit | I21: 4.29 | J21: =IF(OR(G21="",I21=""),"",G21*IF(H21="g",1,IF(H21="kg",1000,SUMIFS('Unit conversions'!$C:$C,'Unit conversions'!$A:$A,$A21,'Unit conversions'!$B:$B,H21)))) -> 600 | K21: =IF(OR(J21="",J21=0),"",I21/J21*100) -> 0.715 | L21: =IF(OR(G21="",I21=""),"",IF(OR(H21="g",H21="ml"),I21/G21*100,I21/G21)) -> 0.3575 | M21: =IF(H21="","",IF(OR(H21="g",H21="ml"),"100 "&H21,H21)) -> unit | N21: Provigo listing | O21: https://www.provigo.ca/en/food/dairy-eggs/egg-egg-substitutes/whole-eggs/c/29781 | P21: 1 egg = 50 g (your note).
A22: Emmental | C22: 371 | D22: 27 | E22: Your nutrition_db.xlsx | J22: =IF(OR(G22="",I22=""),"",G22*IF(H22="g",1,IF(H22="kg",1000,SUMIFS('Unit conversions'!$C:$C,'Unit conversions'!$A:$A,$A22,'Unit conversions'!$B:$B,H22)))) | K22: =IF(OR(J22="",J22=0),"",I22/J22*100) | L22: =IF(OR(G22="",I22=""),"",IF(OR(H22="g",H22="ml"),I22/G22*100,I22/G22)) | M22: =IF(H22="","",IF(OR(H22="g",H22="ml"),"100 "&H22,H22)) | N22: Not priced yet | P22: Not used in your current recipes.
A23: Garlic | C23: 149 | D23: 6.4 | E23: Your nutrition_db.xlsx | F23: Rooster Garlic Bulbs, 3-count (90 g) | G23: 90 | H23: g | I23: 1 | J23: =IF(OR(G23="",I23=""),"",G23*IF(H23="g",1,IF(H23="kg",1000,SUMIFS('Unit conversions'!$C:$C,'Unit conversions'!$A:$A,$A23,'Unit conversions'!$B:$B,H23)))) -> 90 | K23: =IF(OR(J23="",J23=0),"",I23/J23*100) -> 1.1111111 | L23: =IF(OR(G23="",I23=""),"",IF(OR(H23="g",H23="ml"),I23/G23*100,I23/G23)) -> 1.1111111 | M23: =IF(H23="","",IF(OR(H23="g",H23="ml"),"100 "&H23,H23)) -> 100 g | N23: Provigo listing | O23: https://www.provigo.ca/en/food/fruits-vegetables/fresh-vegetables/c/28195 | P23: 1 clove = 5 g (your note).
A24: Gnocchi | C24: 190 | D24: 5 | E24: Your nutrition_db.xlsx | F24: PC Splendido Gnocchi 500 g | G24: 500 | H24: g | I24: 3.3 | J24: =IF(OR(G24="",I24=""),"",G24*IF(H24="g",1,IF(H24="kg",1000,SUMIFS('Unit conversions'!$C:$C,'Unit conversions'!$A:$A,$A24,'Unit conversions'!$B:$B,H24)))) -> 500 | K24: =IF(OR(J24="",J24=0),"",I24/J24*100) -> 0.66 | L24: =IF(OR(G24="",I24=""),"",IF(OR(H24="g",H24="ml"),I24/G24*100,I24/G24)) -> 0.66 | M24: =IF(H24="","",IF(OR(H24="g",H24="ml"),"100 "&H24,H24)) -> 100 g | N24: Provigo unit price (derived) | O24: https://www.provigo.ca/en/food/pantry/pasta-pasta-sauce/dry-pasta/c/29680 | P24: Provigo shows $0.66/100 g. Not used in your current recipes.
A25: Greek yogurt | B25: plain greek yogurt | C25: 59 | D25: 10.2 | E25: USDA FoodData Central (typical value) - plain nonfat | F25: PC Plain Greek Yogurt 0% 750 g | G25: 750 | H25: g | I25: 5.5 | J25: =IF(OR(G25="",I25=""),"",G25*IF(H25="g",1,IF(H25="kg",1000,SUMIFS('Unit conversions'!$C:$C,'Unit conversions'!$A:$A,$A25,'Unit conversions'!$B:$B,H25)))) -> 750 | K25: =IF(OR(J25="",J25=0),"",I25/J25*100) -> 0.73333333 | L25: =IF(OR(G25="",I25=""),"",IF(OR(H25="g",H25="ml"),I25/G25*100,I25/G25)) -> 0.73333333 | M25: =IF(H25="","",IF(OR(H25="g",H25="ml"),"100 "&H25,H25)) -> 100 g | N25: Provigo unit price (derived) | O25: https://www.provigo.ca/en/food/dairy-eggs/yogurt/c/28227?page=1 | P25: Provigo shows $0.73/100 g. Nutrition assumes 0% M.F.; a 2% yogurt has more calories.
A26: Green beans | C26: 31 | D26: 1.8 | E26: USDA FoodData Central (typical value) | F26: Green beans, loose (sold by weight) | G26: 100 | H26: g | I26: 0.88 | J26: =IF(OR(G26="",I26=""),"",G26*IF(H26="g",1,IF(H26="kg",1000,SUMIFS('Unit conversions'!$C:$C,'Unit conversions'!$A:$A,$A26,'Unit conversions'!$B:$B,H26)))) -> 100 | K26: =IF(OR(J26="",J26=0),"",I26/J26*100) -> 0.88 | L26: =IF(OR(G26="",I26=""),"",IF(OR(H26="g",H26="ml"),I26/G26*100,I26/G26)) -> 0.88 | M26: =IF(H26="","",IF(OR(H26="g",H26="ml"),"100 "&H26,H26)) -> 100 g | N26: Provigo listing | O26: https://www.provigo.ca/en/food/fruits-vegetables/fresh-vegetables/peas-beans-corn/c/29597 | P26: $0.88/100 g ($3.99/lb). Sold by weight, so any amount can be bought (priced in 100 g steps here).
A27: Ham | C27: 112 | D27: 21 | E27: Your nutrition_db.xlsx | J27: =IF(OR(G27="",I27=""),"",G27*IF(H27="g",1,IF(H27="kg",1000,SUMIFS('Unit conversions'!$C:$C,'Unit conversions'!$A:$A,$A27,'Unit conversions'!$B:$B,H27)))) | K27: =IF(OR(J27="",J27=0),"",I27/J27*100) | L27: =IF(OR(G27="",I27=""),"",IF(OR(H27="g",H27="ml"),I27/G27*100,I27/G27)) | M27: =IF(H27="","",IF(OR(H27="g",H27="ml"),"100 "&H27,H27)) | N27: Not priced yet | P27: Not used in your current recipes. One slice is 45 g (your note).
A28: Honey | C28: 304 | D28: 0.3 | E28: USDA FoodData Central (typical value) | F28: Billy Bee Pure Natural White Honey 500 g | G28: 500 | H28: g | I28: 10.99 | J28: =IF(OR(G28="",I28=""),"",G28*IF(H28="g",1,IF(H28="kg",1000,SUMIFS('Unit conversions'!$C:$C,'Unit conversions'!$A:$A,$A28,'Unit conversions'!$B:$B,H28)))) -> 500 | K28: =IF(OR(J28="",J28=0),"",I28/J28*100) -> 2.198 | L28: =IF(OR(G28="",I28=""),"",IF(OR(H28="g",H28="ml"),I28/G28*100,I28/G28)) -> 2.198 | M28: =IF(H28="","",IF(OR(H28="g",H28="ml"),"100 "&H28,H28)) -> 100 g | N28: Provigo listing | O28: https://www.provigo.ca/en/food/pantry/honey-syrups-spreads/jams-sweet-spreads/c/29677?page=2 | P28: Regular price; listed at $8.00 on sale.
A29: Jalapeño | B29: jalapeno | C29: 29 | D29: 0.9 | E29: USDA FoodData Central (typical value) | F29: Jalapeño pepper, each | G29: 1 | H29: piece | I29: 0.69 | J29: =IF(OR(G29="",I29=""),"",G29*IF(H29="g",1,IF(H29="kg",1000,SUMIFS('Unit conversions'!$C:$C,'Unit conversions'!$A:$A,$A29,'Unit conversions'!$B:$B,H29)))) -> 25 | K29: =IF(OR(J29="",J29=0),"",I29/J29*100) -> 2.76 | L29: =IF(OR(G29="",I29=""),"",IF(OR(H29="g",H29="ml"),I29/G29*100,I29/G29)) -> 0.69 | M29: =IF(H29="","",IF(OR(H29="g",H29="ml"),"100 "&H29,H29)) -> piece | N29: Your recipe sheet | O29: Your recipe sheet (beef_taco_potato_bowl.xlsx) | P29: 1 piece ~ 25 g (assumption; nutrition is negligible).
A30: Ketchup | C30: 101 | D30: 1 | E30: USDA FoodData Central (typical value) | F30: Heinz Tomato Ketchup 750 ml | G30: 750 | H30: ml | I30: 6 | J30: =IF(OR(G30="",I30=""),"",G30*IF(H30="g",1,IF(H30="kg",1000,SUMIFS('Unit conversions'!$C:$C,'Unit conversions'!$A:$A,$A30,'Unit conversions'!$B:$B,H30)))) -> 862.5 | K30: =IF(OR(J30="",J30=0),"",I30/J30*100) -> 0.69565217 | L30: =IF(OR(G30="",I30=""),"",IF(OR(H30="g",H30="ml"),I30/G30*100,I30/G30)) -> 0.8 | M30: =IF(H30="","",IF(OR(H30="g",H30="ml"),"100 "&H30,H30)) -> 100 ml | N30: Provigo unit price (derived) | O30: https://www.provigo.ca/en/food/pantry/condiments-sauces/ketchup/c/29690 | P30: Provigo shows $0.80/100 ml.
A31: Mayo | B31: mayonnaise | C31: 680 | D31: 1 | E31: USDA FoodData Central (typical value) | F31: PC Mayonnaise 890 ml | G31: 890 | H31: ml | I31: 6 | J31: =IF(OR(G31="",I31=""),"",G31*IF(H31="g",1,IF(H31="kg",1000,SUMIFS('Unit conversions'!$C:$C,'Unit conversions'!$A:$A,$A31,'Unit conversions'!$B:$B,H31)))) -> 809.9 | K31: =IF(OR(J31="",J31=0),"",I31/J31*100) -> 0.7408322 | L31: =IF(OR(G31="",I31=""),"",IF(OR(H31="g",H31="ml"),I31/G31*100,I31/G31)) -> 0.6741573 | M31: =IF(H31="","",IF(OR(H31="g",H31="ml"),"100 "&H31,H31)) -> 100 ml | N31: Provigo listing | O31: https://www.provigo.ca/en/food/pantry/condiments-sauces/c/28243?page=2 | P31: Hellmann's Real 890 ml is about $0.90/100 ml. Nutrition is for regular (full-fat) mayo.
A32: Mushroom | B32: mushrooms | C32: 22 | D32: 3 | E32: Your nutrition_db.xlsx | J32: =IF(OR(G32="",I32=""),"",G32*IF(H32="g",1,IF(H32="kg",1000,SUMIFS('Unit conversions'!$C:$C,'Unit conversions'!$A:$A,$A32,'Unit conversions'!$B:$B,H32)))) | K32: =IF(OR(J32="",J32=0),"",I32/J32*100) | L32: =IF(OR(G32="",I32=""),"",IF(OR(H32="g",H32="ml"),I32/G32*100,I32/G32)) | M32: =IF(H32="","",IF(OR(H32="g",H32="ml"),"100 "&H32,H32)) | N32: Not priced yet | P32: Not used in your current recipes.
A33: Noodles | C33: 380 | D33: 8 | E33: Your nutrition_db.xlsx | J33: =IF(OR(G33="",I33=""),"",G33*IF(H33="g",1,IF(H33="kg",1000,SUMIFS('Unit conversions'!$C:$C,'Unit conversions'!$A:$A,$A33,'Unit conversions'!$B:$B,H33)))) | K33: =IF(OR(J33="",J33=0),"",I33/J33*100) | L33: =IF(OR(G33="",I33=""),"",IF(OR(H33="g",H33="ml"),I33/G33*100,I33/G33)) | M33: =IF(H33="","",IF(OR(H33="g",H33="ml"),"100 "&H33,H33)) | N33: Not priced yet | P33: Not used in your current recipes. ~90 g dry per pack (your note).
A34: Onion | B34: onions | C34: 30 | D34: 1 | E34: Your nutrition_db.xlsx | F34: Farmer's Market Yellow Onions, 3 lb bag (1.36 kg) | G34: 1360 | H34: g | I34: 3.79 | J34: =IF(OR(G34="",I34=""),"",G34*IF(H34="g",1,IF(H34="kg",1000,SUMIFS('Unit conversions'!$C:$C,'Unit conversions'!$A:$A,$A34,'Unit conversions'!$B:$B,H34)))) -> 1360 | K34: =IF(OR(J34="",J34=0),"",I34/J34*100) -> 0.27867647 | L34: =IF(OR(G34="",I34=""),"",IF(OR(H34="g",H34="ml"),I34/G34*100,I34/G34)) -> 0.27867647 | M34: =IF(H34="","",IF(OR(H34="g",H34="ml"),"100 "&H34,H34)) -> 100 g | N34: Provigo listing | O34: https://www.provigo.ca/en/food/fruits-vegetables/fresh-fruits/avocado-tropical-fruits/c/29723 | P34: Not used in your current recipes. 1 onion = 150 g (your note).
A35: Pasta | C35: 350 | D35: 13 | E35: Your nutrition_db.xlsx | F35: No Name Spaghetti / Penne 900 g | G35: 900 | H35: g | I35: 2.5 | J35: =IF(OR(G35="",I35=""),"",G35*IF(H35="g",1,IF(H35="kg",1000,SUMIFS('Unit conversions'!$C:$C,'Unit conversions'!$A:$A,$A35,'Unit conversions'!$B:$B,H35)))) -> 900 | K35: =IF(OR(J35="",J35=0),"",I35/J35*100) -> 0.27777778 | L35: =IF(OR(G35="",I35=""),"",IF(OR(H35="g",H35="ml"),I35/G35*100,I35/G35)) -> 0.27777778 | M35: =IF(H35="","",IF(OR(H35="g",H35="ml"),"100 "&H35,H35)) -> 100 g | N35: Provigo listing | O35: https://www.provigo.ca/en/food/pantry/pasta-pasta-sauce/dry-pasta/c/29680 | P35: Dry weight.
A36: Peanut butter | C36: 605 | D36: 27 | E36: Your nutrition_db.xlsx | F36: Kraft Smooth Peanut Butter 1 kg | G36: 1000 | H36: g | I36: 7.5 | J36: =IF(OR(G36="",I36=""),"",G36*IF(H36="g",1,IF(H36="kg",1000,SUMIFS('Unit conversions'!$C:$C,'Unit conversions'!$A:$A,$A36,'Unit conversions'!$B:$B,H36)))) -> 1000 | K36: =IF(OR(J36="",J36=0),"",I36/J36*100) -> 0.75 | L36: =IF(OR(G36="",I36=""),"",IF(OR(H36="g",H36="ml"),I36/G36*100,I36/G36)) -> 0.75 | M36: =IF(H36="","",IF(OR(H36="g",H36="ml"),"100 "&H36,H36)) -> 100 g | N36: Provigo listing | O36: https://www.provigo.ca/en/food/snacks-chips-candy/c/57025 | P36: Regular price; listed at $7.00 on sale.
A37: Black pepper | B37: black pepper, ground pepper | C37: 0 | D37: 0 | E37: Your nutrition_db.xlsx | J37: =IF(OR(G37="",I37=""),"",G37*IF(H37="g",1,IF(H37="kg",1000,SUMIFS('Unit conversions'!$C:$C,'Unit conversions'!$A:$A,$A37,'Unit conversions'!$B:$B,H37)))) | K37: =IF(OR(J37="",J37=0),"",I37/J37*100) | L37: =IF(OR(G37="",I37=""),"",IF(OR(H37="g",H37="ml"),I37/G37*100,I37/G37)) | M37: =IF(H37="","",IF(OR(H37="g",H37="ml"),"100 "&H37,H37)) | N37: Not priced yet | P37: Not used in your current recipes (negligible calories).
A38: Potatoes | B38: potato | C38: 77 | D38: 2 | E38: USDA FoodData Central (typical value) | F38: PC Yellow Mini Potatoes 680 g | G38: 680 | H38: g | I38: 5 | J38: =IF(OR(G38="",I38=""),"",G38*IF(H38="g",1,IF(H38="kg",1000,SUMIFS('Unit conversions'!$C:$C,'Unit conversions'!$A:$A,$A38,'Unit conversions'!$B:$B,H38)))) -> 680 | K38: =IF(OR(J38="",J38=0),"",I38/J38*100) -> 0.73529412 | L38: =IF(OR(G38="",I38=""),"",IF(OR(H38="g",H38="ml"),I38/G38*100,I38/G38)) -> 0.73529412 | M38: =IF(H38="","",IF(OR(H38="g",H38="ml"),"100 "&H38,H38)) -> 100 g | N38: Your recipe sheet | O38: Your recipe sheet (beef_taco_potato_bowl.xlsx); Provigo shows $0.74/100 g | P38: A 10 lb (4.54 kg) bag of Farmer's Market potatoes is about $5.99 ($0.13/100 g) if you would rather buy in bulk.
A39: Protein powder | C39: 400 | D39: 80 | E39: Approximate (typical whey powder) | F39: Whey protein powder, ~908 g tub | G39: 908 | H39: g | I39: 45 | J39: =IF(OR(G39="",I39=""),"",G39*IF(H39="g",1,IF(H39="kg",1000,SUMIFS('Unit conversions'!$C:$C,'Unit conversions'!$A:$A,$A39,'Unit conversions'!$B:$B,H39)))) -> 908 | K39: =IF(OR(J39="",J39=0),"",I39/J39*100) -> 4.9559471 | L39: =IF(OR(G39="",I39=""),"",IF(OR(H39="g",H39="ml"),I39/G39*100,I39/G39)) -> 4.9559471 | M39: =IF(H39="","",IF(OR(H39="g",H39="ml"),"100 "&H39,H39)) -> 100 g | N39: ESTIMATE - verify | O39: Not a Provigo price - no usable Provigo listing found | P39: Replace with your own tub's price and weight. 1 scoop = 30 g (~24 g protein).
A40: Rice | C40: 345 | D40: 8.5 | E40: Your nutrition_db.xlsx | F40: No Name Long Grain White Rice 2 kg | G40: 2000 | H40: g | I40: 7.99 | J40: =IF(OR(G40="",I40=""),"",G40*IF(H40="g",1,IF(H40="kg",1000,SUMIFS('Unit conversions'!$C:$C,'Unit conversions'!$A:$A,$A40,'Unit conversions'!$B:$B,H40)))) -> 2000 | K40: =IF(OR(J40="",J40=0),"",I40/J40*100) -> 0.3995 | L40: =IF(OR(G40="",I40=""),"",IF(OR(H40="g",H40="ml"),I40/G40*100,I40/G40)) -> 0.3995 | M40: =IF(H40="","",IF(OR(H40="g",H40="ml"),"100 "&H40,H40)) -> 100 g | N40: Provigo listing | O40: https://www.provigo.ca/en/food/pantry/rice/long-grain/c/29682 | P40: Dry weight.
...

Sheet Unit conversions
A1: Grams per recipe unit (for 'ml' rows: grams per millilitre)
A2: Unit names must be singular: g, ml, piece, unit, strip, slice, pack, scoop, clove, teaspoon, tablespoon, cup. 'g', 'kg' and 'l' work without a row (ml uses 1 g/ml unless a row says otherwise).
A3: Ingredient | B3: Recipe unit | C3: Grams per unit | D3: Note
A4: Avocado | B4: piece | C4: 100 | D4: 1 avocado = 100 g (your note)
A5: Bacon | B5: strip | C5: 8 | D5: 1 cooked strip = 8 g
A6: Baking powder | B6: tablespoon | C6: 13.8 | D6: 1 tbsp
A7: Beef broth | B7: piece | C7: 10 | D7: 1 bouillon cube (assumption)
A8: Courgette | B8: piece | C8: 400 | D8: 1 courgette = 400 g (your note)
A9: Egg | B9: unit | C9: 50 | D9: 1 egg = 50 g (your note)
A10: Garlic | B10: clove | C10: 5 | D10: 1 clove = 5 g (your note)
A11: Ham | B11: slice | C11: 45 | D11: 1 slice = 45 g (your note)
A12: Honey | B12: tablespoon | C12: 21 | D12: 1 tbsp
A13: Honey | B13: teaspoon | C13: 7 | D13: 1 tsp
A14: Jalapeño | B14: piece | C14: 25 | D14: 1 pepper (assumption)
A15: Ketchup | B15: ml | C15: 1.15 | D15: grams per ml
... A40: Salsa | B40: ml | C40: 1.08 | D40: grams per ml (259 g per 240 ml cup)
